src/constellation/test_data/symbology.json
{
    "result": {
        "MESH6": [
            {
                "d0": "2024-12-25",
                "d1": "2025-01-25",
                "s": "42003800"
            }
        ],
        "MESZ5": [
            {
                "d0": "2024-12-25",
                "d1": "2025-01-25",
                "s": "42004164"
            }
        ],
        "MESU5-MESH6": [
            {
                "d0": "2024-12-25",
                "d1": "2025-01-25",
                "s": "42017651"
            }
        ],
        "MESM5-MESU5": [
            {
                "d0": "2024-12-25",
                "d1": "2025-01-25",
                "s": "42006431"
            }
        ],
        "MESU5-MESZ5": [
            {
                "d0": "2024-12-25",
                "d1": "2025-01-25",
                "s": "42005309"
            }
        ],
        "MESM5-MESH6": [
            {
                "d0": "2024-12-25",
                "d1": "2025-01-25",
                "s": "42012240"
            }
        ],
        "MESH5-MESU5": [
            {
                "d0": "2024-12-25",
                "d1": "2025-01-25",
                "s": "42008830"
            }
        ],
        "MESM5": [
            {
                "d0": "2024-12-25",
                "d1": "2025-01-25",
                "s": "42003627"
            }
        ],
        "MESM5-MESZ5": [
            {
                "d0": "2024-12-25",
                "d1": "2025-01-25",
                "s": "42004736"
            }
        ],
        "MESH5-MESM5": [
            {
                "d0": "2024-12-25",
                "d1": "2025-01-25",
                "s": "42013621"
            }
        ],
        "MESH5": [
            {
                "d0": "2024-12-25",
                "d1": "2025-01-25",
                "s": "42005347"
            }
        ],
        "MESH5-MESZ5": [
            {
                "d0": "2024-12-25",
                "d1": "2025-01-25",
                "s": "42010278"
            }
        ],
        "MESH5-MESH6": [
            {
                "d0": "2024-12-25",
                "d1": "2025-01-25",
                "s": "42009224"
            }
        ],
        "MESU5": [
            {
                "d0": "2024-12-25",
                "d1": "2025-01-25",
                "s": "42002651"
            }
        ],
        "MESZ5-MESH6": [
            {
                "d0": "2024-12-25",
                "d1": "2025-01-25",
                "s": "42015635"
            }
        ]
    },
    "symbols": [
        "MES.FUT"
    ],
    "stype_in": "parent",
    "stype_out": "instrument_id",
    "start_date": "2024-12-25",
    "end_date": "2025-01-25",
    "partial": [],
    "not_found": [],
    "message": "OK",
    "status": 0
}
